Workbook

Sheet Data
A1: stair.thisTrialN | B1: stair.stepSize | C1: stair.intensity | D1: thisRow.t | E1: notes | F1: piloting | G1: trial.started | H1: fixation.started | I1: grating.started | J1: key_resp.started | K1: fixation.stopped | L1: grating.stopped | M1: trial.stopped | N1: corrAns | O1: tilt | P1: key_resp.corr | Q1: stair.response | R1: key_resp.rt | S1: participant | T1: session | U1: date | V1: expName | W1: expVersion | X1: psychopyVersion | Y1: frameRate | Z1: expStart
A2: 0 | B2: 2 | C2: 10 | D2: 0.0160065 | F2: =FALSE() -> FALSE | G2: 0.0097666001 | H2: 0.0160065 | I2: 0.5166049 | J2: 0.5166049 | K2: 0.5258715 | L2: 0.8092896 | M2: 2.4511876 | N2: right | O2: 10 | P2: 1 | Q2: 1 | R2: 1.8956083 | S2: 310387 | T2: 1 | U2: 2026-10-03_23h26.52.674 | V2: adaptive_staircase1 | X2: 2026.2.4 | Y2: 120.12286 | Z2: 2026-10-03 23h26.52.704802 +0530
A3: 1 | B3: 2 | C3: 8 | D3: 2.456848 | G3: 2.4514464 | H3: 2.456848 | I3: 2.9416745 | J3: 2.9416745 | K3: 2.9505827 | L3: 3.2342434 | M3: 4.7177357 | N3: right | O3: 8 | P3: 1 | Q3: 1 | R3: 1.7692863 | S3: 310387 | T3: 1 | U3: 2026-10-03_23h26.52.674 | V3: adaptive_staircase1 | X3: 2026.2.4 | Y3: 120.12286 | Z3: 2026-10-03 23h26.52.704802 +0530
A4: 2 | B4: 2 | C4: 6 | D4: 4.7248162 | G4: 4.7180075 | H4: 4.7248162 | I4: 5.2091831 | J4: 5.2091831 | K4: 5.217778 | L4: 5.5005404 | M4: 5.568486 | N4: right | O4: 6 | P4: 1 | Q4: 1 | R4: 0.3558531 | S4: 310387 | T4: 1 | U4: 2026-10-03_23h26.52.674 | V4: adaptive_staircase1 | X4: 2026.2.4 | Y4: 120.12286 | Z4: 2026-10-03 23h26.52.704802 +0530
A5: 3 | B5: 1 | C5: 4 | D5: 5.5747372 | G5: 5.5688396 | H5: 5.5747372 | I5: 6.067352 | J5: 6.067352 | K5: 6.067352 | L5: 6.3593267 | M5: 6.442233 | N5: right | O5: -4 | P5: 0 | Q5: 0 | R5: 0.3693895 | S5: 310387 | T5: 1 | U5: 2026-10-03_23h26.52.674 | V5: adaptive_staircase1 | X5: 2026.2.4 | Y5: 120.12286 | Z5: 2026-10-03 23h26.52.704802 +0530
A6: 4 | B6: 1 | C6: 5 | D6: 6.4499451 | G6: 6.4424822 | H6: 6.4499451 | I6: 6.9335844 | J6: 6.9335844 | K6: 6.9418116 | M6: 7.2015595 | N6: right | O6: -5 | P6: 1 | Q6: 1 | R6: 0.2666039 | S6: 310387 | T6: 1 | U6: 2026-10-03_23h26.52.674 | V6: adaptive_staircase1 | X6: 2026.2.4 | Y6: 120.12286 | Z6: 2026-10-03 23h26.52.704802 +0530
A7: 5 | B7: 1 | C7: 5 | D7: 7.2084928 | G7: 7.2018355 | H7: 7.2084928 | I7: 7.7004263 | J7: 7.7004263 | K7: 7.7004263 | L7: 7.99253 | M7: 8.3121676 | N7: right | O7: 5 | P7: 0 | Q7: 0 | R7: 0.6083126 | S7: 310387 | T7: 1 | U7: 2026-10-03_23h26.52.674 | V7: adaptive_staircase1 | X7: 2026.2.4 | Y7: 120.12286 | Z7: 2026-10-03 23h26.52.704802 +0530
A8: 6 | B8: 1 | C8: 6 | D8: 8.3236538 | G8: 8.312454 | H8: 8.3236538 | I8: 8.8087507 | J8: 8.8087507 | K8: 8.817764 | L8: 9.1002634 | M8: 9.3088832 | N8: right | O8: 6 | P8: 1 | Q8: 1 | R8: 0.496119 | S8: 310387 | T8: 1 | U8: 2026-10-03_23h26.52.674 | V8: adaptive_staircase1 | X8: 2026.2.4 | Y8: 120.12286 | Z8: 2026-10-03 23h26.52.704802 +0530
A9: 7 | B9: 1 | C9: 6 | D9: 9.3166531 | G9: 9.3091367 | H9: 9.3166531 | I9: 9.8005262 | J9: 9.8005262 | K9: 9.8086263 | L9: 10.09302 | M9: 10.266635 | N9: right | O9: -6 | P9: 0 | Q9: 0 | R9: 0.4525893 | S9: 310387 | T9: 1 | U9: 2026-10-03_23h26.52.674 | V9: adaptive_staircase1 | X9: 2026.2.4 | Y9: 120.12286 | Z9: 2026-10-03 23h26.52.704802 +0530
A10: 8 | B10: 1 | C10: 7 | D10: 10.275624 | G10: 10.267012 | H10: 10.275624 | I10: 10.758389 | J10: 10.758389 | K10: 10.767541 | L10: 11.050721 | M10: 11.075052 | N10: right | O10: 7 | P10: 1 | Q10: 1 | R10: 0.3117437 | S10: 310387 | T10: 1 | U10: 2026-10-03_23h26.52.674 | V10: adaptive_staircase1 | X10: 2026.2.4 | Y10: 120.12286 | Z10: 2026-10-03 23h26.52.704802 +0530
A11: 9 | B11: 1 | C11: 7 | D11: 11.083929 | G11: 11.075293 | H11: 11.083929 | I11: 11.566844 | J11: 11.566844 | K11: 11.575564 | L11: 11.859316 | M11: 12.092432 | N11: right | O11: 7 | P11: 1 | Q11: 1 | R11: 0.5171996 | S11: 310387 | T11: 1 | U11: 2026-10-03_23h26.52.674 | V11: adaptive_staircase1 | X11: 2026.2.4 | Y11: 120.12286 | Z11: 2026-10-03 23h26.52.704802 +0530
A12: 10 | B12: 1 | C12: 7 | D12: 12.100243 | G12: 12.092707 | H12: 12.100243 | I12: 12.583872 | J12: 12.583872 | K12: 12.592096 | L12: 12.876168 | M12: 12.925381 | N12: right | O12: 7 | P12: 1 | Q12: 1 | R12: 0.3362953 | S12: 310387 | T12: 1 | U12: 2026-10-03_23h26.52.674 | V12: adaptive_staircase1 | X12: 2026.2.4 | Y12: 120.12286 | Z12: 2026-10-03 23h26.52.704802 +0530
A13: 11 | B13: 0.5 | C13: 6 | D13: 12.933107 | G13: 12.925655 | H13: 12.933107 | I13: 13.41722 | J13: 13.41722 | K13: 13.425697 | L13: 13.710553 | M13: 13.876465 | N13: right | O13: -6 | P13: 0 | Q13: 0 | R13: 0.4557302 | S13: 310387 | T13: 1 | U13: 2026-10-03_23h26.52.674 | V13: adaptive_staircase1 | X13: 2026.2.4 | Y13: 120.12286 | Z13: 2026-10-03 23h26.52.704802 +0530
A14: 12 | B14: 0.5 | C14: 6.5 | D14: 13.883226 | G14: 13.8768 | H14: 13.883226 | I14: 14.375268 | J14: 14.375268 | K14: 14.375268 | M14: 14.643002 | N14: right | O14: 6.5 | P14: 1 | Q14: 1 | R14: 0.2621924 | S14: 310387 | T14: 1 | U14: 2026-10-03_23h26.52.674 | V14: adaptive_staircase1 | X14: 2026.2.4 | Y14: 120.12286 | Z14: 2026-10-03 23h26.52.704802 +0530
A15: 13 | B15: 0.5 | C15: 6.5 | D15: 14.649711 | G15: 14.643289 | H15: 14.649711 | I15: 15.133853 | J15: 15.133853 | K15: 15.142218 | L15: 15.425718 | M15: 15.686338 | N15: right | O15: 6.5 | P15: 1 | Q15: 1 | R15: 0.5487146 | S15: 310387 | T15: 1 | U15: 2026-10-03_23h26.52.674 | V15: adaptive_staircase1 | X15: 2026.2.4 | Y15: 120.12286 | Z15: 2026-10-03 23h26.52.704802 +0530
A16: 14 | B16: 0.5 | C16: 6.5 | D16: 15.69912 | G16: 15.686668 | H16: 15.69912 | I16: 16.184107 | J16: 16.184107 | K16: 16.192205 | L16: 16.475494 | M16: 16.633288 | N16: right | O16: -6.5 | P16: 0 | Q16: 0 | R16: 0.4446017 | S16: 310387 | T16: 1 | U16: 2026-10-03_23h26.52.674 | V16: adaptive_staircase1 | X16: 2026.2.4 | Y16: 120.12286 | Z16: 2026-10-03 23h26.52.704802 +0530
A17: 15 | B17: 0.5 | C17: 7 | D17: 16.64159 | G17: 16.633528 | H17: 16.64159 | I17: 17.124863 | J17: 17.124863 | K17: 17.133219 | M17: 17.393623 | N17: right | O17: -7 | P17: 1 | Q17: 1 | R17: 0.2668481 | S17: 310387 | T17: 1 | U17: 2026-10-03_23h26.52.674 | V17: adaptive_staircase1 | X17: 2026.2.4 | Y17: 120.12286 | Z17: 2026-10-03 23h26.52.704802 +0530
A18: 16 | B18: 0.5 | C18: 7 | D18: 17.399803 | G18: 17.393902 | H18: 17.399803 | I18: 17.89187 | J18: 17.89187 | K18: 17.89187 | L18: 18.183267 | M18: 18.392531 | N18: right | O18: -7 | P18: 0 | Q18: 0 | R18: 0.4934279 | S18: 310387 | T18: 1 | U18: 2026-10-03_23h26.52.674 | V18: adaptive_staircase1 | X18: 2026.2.4 | Y18: 120.12286 | Z18: 2026-10-03 23h26.52.704802 +0530
A19: 17 | B19: 0.5 | C19: 7.5 | D19: 18.399496 | G19: 18.392875 | H19: 18.399496 | I19: 18.883595 | J19: 18.883595 | K19: 18.892326 | M19: 19.118243 | N19: right | O19: 7.5 | P19: 1 | Q19: 1 | R19: 0.2305186 | S19: 310387 | T19: 1 | U19: 2026-10-03_23h26.52.674 | V19: adaptive_staircase1 | X19: 2026.2.4 | Y19: 120.12286 | Z19: 2026-10-03 23h26.52.704802 +0530
A20: 18 | B20: 0.5 | C20: 7.5 | D20: 19.124802 | G20: 19.118557 | H20: 19.124802 | I20: 19.615646 | J20: 19.615646 | K20: 19.615646 | L20: 19.909357 | M20: 20.000403 | N20: right | O20: -7.5 | P20: 0 | Q20: 0 | R20: 0.3809851 | S20: 310387 | T20: 1 | U20: 2026-10-03_23h26.52.674 | V20: adaptive_staircase1 | X20: 2026.2.4 | Y20: 120.12286 | Z20: 2026-10-03 23h26.52.704802 +0530
A21: 19 | B21: 0.5 | C21: 8 | D21: 20.008223 | G21: 20.00074 | H21: 20.008223 | I21: 20.491395 | J21: 20.491395 | K21: 20.500577 | M21: 20.733782 | N21: right | O21: -8 | P21: 1 | Q21: 1 | R21: 0.2369934 | S21: 310387 | T21: 1 | U21: 2026-10-03_23h26.52.674 | V21: adaptive_staircase1 | X21: 2026.2.4 | Y21: 120.12286 | Z21: 2026-10-03 23h26.52.704802 +0530
A22: 20 | B22: 0.5 | C22: 8 | D22: 20.742317 | G22: 20.734066 | H22: 20.742317 | I22: 21.225119 | J22: 21.225119 | K22: 21.233375 | L22: 21.516312 | M22: 21.726342 | N22: right | O22: 8 | P22: 1 | Q22: 1 | R22: 0.4976834 | S22: 310387 | T22: 1 | U22: 2026-10-03_23h26.52.674 | V22: adaptive_staircase1 | X22: 2026.2.4 | Y22: 120.12286 | Z22: 2026-10-03 23h26.52.704802 +0530
A23: 21 | B23: 0.5 | C23: 8 | D23: 21.732826 | G23: 21.726684 | H23: 21.732826 | I23: 22.225405 | J23: 22.225405 | K23: 22.225405 | L23: 22.517164 | M23: 22.575694 | N23: right | O23: -8 | P23: 0 | Q23: 0 | R23: 0.3476061 | S23: 310387 | T23: 1 | U23: 2026-10-03_23h26.52.674 | V23: adaptive_staircase1 | X23: 2026.2.4 | Y23: 120.12286 | Z23: 2026-10-03 23h26.52.704802 +0530
A24: 22 | B24: 0.5 | C24: 8.5 | D24: 22.582822 | G24: 22.575983 | H24: 22.582822 | I24: 23.06669 | J24: 23.06669 | K24: 23.075399 | L24: 23.358652 | M24: 23.376967 | N24: right | O24: 8.5 | P24: 1 | Q24: 1 | R24: 0.3066635 | S24: 310387 | T24: 1 | U24: 2026-10-03_23h26.52.674 | V24: adaptive_staircase1 | X24: 2026.2.4 | Y24: 120.12286 | Z24: 2026-10-03 23h26.52.704802 +0530
A25: 23 | B25: 0.5 | C25: 8.5 | D25: 23.382554 | G25: 23.377224 | H25: 23.382554 | I25: 23.87582 | J25: 23.87582 | K25: 23.87582 | L25: 24.167482 | M25: 24.283516 | N25: right | O25: 8.5 | P25: 1 | Q25: 1 | R25: 0.402064 | S25: 310387 | T25: 1 | U25: 2026-10-03_23h26.52.674 | V25: adaptive_staircase1 | X25: 2026.2.4 | Y25: 120.12286 | Z25: 2026-10-03 23h26.52.704802 +0530
A26: 24 | B26: 0.5 | C26: 8.5 | D26: 24.29122 | G26: 24.283774 | H26: 24.29122 | I26: 24.775651 | J26: 24.775651 | K26: 24.783346 | L26: 25.066408 | M26: 25.109971 | N26: right | O26: -8.5 | P26: 0 | Q26: 0 | R26: 0.3300191 | S26: 310387 | T26: 1 | U26: 2026-10-03_23h26.52.674 | V26: adaptive_staircase1 | X26: 2026.2.4 | Y26: 120.12286 | Z26: 2026-10-03 23h26.52.704802 +0530
A27: 25 | B27: 0.5 | C27: 9 | D27: 25.12428 | G27: 25.110365 | H27: 25.12428 | I27: 25.607908 | J27: 25.607908 | K27: 25.616617 | L27: 25.900699 | M27: 25.920145 | N27: right | O27: -9 | P27: 1 | Q27: 1 | R27: 0.3093278 | S27: 310387 | T27: 1 | U27: 2026-10-03_23h26.52.674 | V27: adaptive_staircase1 | X27: 2026.2.4 | Y27: 120.12286 | Z27: 2026-10-03 23h26.52.704802 +0530
A28: 26 | B28: 0.5 | C28: 9 | D28: 25.932134 | G28: 25.92038 | H28: 25.932134 | I28: 26.416777 | J28: 26.416777 | K28: 26.425724 | M28: 26.694281 | N28: right | O28: 9 | P28: 1 | Q28: 1 | R28: 0.2752617 | S28: 310387 | T28: 1 | U28: 2026-10-03_23h26.52.674 | V28: adaptive_staircase1 | X28: 2026.2.4 | Y28: 120.12286 | Z28: 2026-10-03 23h26.52.704802 +0530
A29: 27 | B29: 0.5 | C29: 9 | D29: 26.707012 | G29: 26.694512 | H29: 26.707012 | I29: 27.191335 | J29: 27.191335 | K29: 27.200191 | L29: 27.48362 | M29: 27.599758 | N29: right | O29: 9 | P29: 1 | Q29: 1 | R29: 0.3944238 | S29: 310387 | T29: 1 | U29: 2026-10-03_23h26.52.674 | V29: adaptive_staircase1 | X29: 2026.2.4 | Y29: 120.12286 | Z29: 2026-10-03 23h26.52.704802 +0530
A30: 28 | B30: 0.5 | C30: 8.5 | D30: 27.607906 | G30: 27.600055 | H30: 27.607906 | I30: 28.091511 | J30: 28.091511 | K30: 28.100467 | L30: 28.383471 | M30: 28.416501 | N30: right | O30: -8.5 | P30: 0 | Q30: 0 | R30: 0.3177362 | S30: 310387 | T30: 1 | U30: 2026-10-03_23h26.52.674 | V30: adaptive_staircase1 | X30: 2026.2.4 | Y30: 120.12286 | Z30: 2026-10-03 23h26.52.704802 +0530
A31: 29 | B31: 0.5 | C31: 9 | D31: 28.425009 | G31: 28.41676 | H31: 28.425009 | I31: 28.908181 | J31: 28.908181 | K31: 28.916054 | L31: 29.202517 | M31: 29.203072 | N31: right | O31: -9 | P31: 1 | Q31: 1 | R31: 0.2915778 | S31: 310387 | T31: 1 | U31: 2026-10-03_23h26.52.674 | V31: adaptive_staircase1 | X31: 2026.2.4 | Y31: 120.12286 | Z31: 2026-10-03 23h26.52.704802 +0530
A32: 30 | B32: 0.5 | C32: 9 | D32: 29.215828 | G32: 29.203343 | H32: 29.215828 | I32: 29.69946 | J32: 29.69946 | K32: 29.708174 | L32: 29.991566 | M32: 30.183673 | N32: right | O32: -9 | P32: 0 | Q32: 0 | R32: 0.4798406 | S32: 310387 | T32: 1 | U32: 2026-10-03_23h26.52.674 | V32: adaptive_staircase1 | X32: 2026.2.4 | Y32: 120.12286 | Z32: 2026-10-03 23h26.52.704802 +0530
A33: 31 | B33: 0.5 | C33: 9.5 | D33: 30.191587 | G33: 30.183966 | H33: 30.191587 | I33: 30.67483 | J33: 30.67483 | K33: 30.682457 | L33: 30.967138 | M33: 31.057791 | N33: right | O33: -9.5 | P33: 0 | Q33: 0 | R33: 0.3787801 | S33: 310387 | T33: 1 | U33: 2026-10-03_23h26.52.674 | V33: adaptive_staircase1 | X33: 2026.2.4 | Y33: 120.12286 | Z33: 2026-10-03 23h26.52.704802 +0530
A34: 32 | B34: 0.5 | C34: 10 | D34: 31.066378 | G34: 31.058066 | H34: 31.066378 | I34: 31.549952 | J34: 31.549952 | K34: 31.55867 | L34: 31.842374 | M34: 31.957631 | N34: right | O34: 10 | P34: 1 | Q34: 1 | R34: 0.3947319 | S34: 310387 | T34: 1 | U34: 2026-10-03_23h26.52.674 | V34: adaptive_staircase1 | X34: 2026.2.4 | Y34: 120.12286 | Z34: 2026-10-03 23h26.52.704802 +0530
A35: 33 | B35: 0.5 | C35: 10 | D35: 31.966362 | G35: 31.957975 | H35: 31.966362 | I35: 32.449789 | J35: 32.449789 | K35: 32.458395 | M35: 32.724518 | N35: right | O35: -10 | P35: 0 | Q35: 0 | R35: 0.2699364 | S35: 310387 | T35: 1 | U35: 2026-10-03_23h26.52.674 | V35: adaptive_staircase1 | X35: 2026.2.4 | Y35: 120.12286 | Z35: 2026-10-03 23h26.52.704802 +0530
A36: 34 | B36: 0.5 | C36: 10.5 | D36: 32.732665 | G36: 32.724763 | H36: 32.732665 | I36: 33.215973 | J36: 33.215973 | K36: 33.225042 | L36: 33.509163 | M36: 33.625229 | N36: right | O36: -10.5 | P36: 0 | Q36: 0 | R36: 0.4027976 | S36: 310387 | T36: 1 | U36: 2026-10-03_23h26.52.674 | V36: adaptive_staircase1 | X36: 2026.2.4 | Y36: 120.12286 | Z36: 2026-10-03 23h26.52.704802 +0530
A37: 35 | B37: 0.5 | C37: 11 | D37: 33.633411 | G37: 33.625544 | H37: 33.633411 | I37: 34.116216 | J37: 34.116216 | K37: 34.124824 | L37: 34.408621 | M37: 34.500786 | N37: right | O37: -11 | P37: 0 | Q37: 0 | R37: 0.3811111 | S37: 310387 | T37: 1 | U37: 2026-10-03_23h26.52.674 | V37: adaptive_staircase1 | X37: 2026.2.4 | Y37: 120.12286 | Z37: 2026-10-03 23h26.52.704802 +0530
A38: 36 | B38: 0.5 | C38: 11.5 | D38: 34.507619 | G38: 34.50106 | H38: 34.507619 | I38: 34.999285 | J38: 34.999285 | K38: 34.999285 | L38: 35.290164 | M38: 35.308219 | N38: right | O38: -11.5 | P38: 0 | Q38: 0 | R38: 0.3042932 | S38: 310387 | T38: 1 | U38: 2026-10-03_23h26.52.674 | V38: adaptive_staircase1 | X38: 2026.2.4 | Y38: 120.12286 | Z38: 2026-10-03 23h26.52.704802 +0530
A39: 37 | B39: 0.5 | C39: 12 | D39: 35.316173 | G39: 35.308448 | H39: 35.316173 | I39: 35.79984 | J39: 35.79984 | K39: 35.808571 | L39: 36.091432 | M39: 36.157004 | N39: right | O39: 12 | P39: 0 | Q39: 0 | R39: 0.3547806 | S39: 310387 | T39: 1 | U39: 2026-10-03_23h26.52.674 | V39: adaptive_staircase1 | X39: 2026.2.4 | Y39: 120.12286 | Z39: 2026-10-03 23h26.52.704802 +0530
A40: 38 | B40: 0.5 | C40: 12.5 | D40: 36.164942 | G40: 36.157169 | H40: 36.164942 | I40: 36.648765 | J40: 36.648765 | K40: 36.65669 | L40: 36.940517 | M40: 37.177707 | N40: right | O40: -12.5 | P40: 0 | Q40: 0 | R40: 0.52546 | S40: 310387 | T40: 1 | U40: 2026-10-03_23h26.52.674 | V40: adaptive_staircase1 | X40: 2026.2.4 | Y40: 120.12286 | Z40: 2026-10-03 23h26.52.704802 +0530
...

Sheet Analysis
A1: Adaptive Staircase – Difference Threshold (average of last five 1-to-0 reversals)
A2: Source: PsychoPy output for participant 310387, session 001 (Data sheet). Green = pulled from Data sheet, blue = typed in from the PsychoPy log file, black = calculated.
A3: Trial | B3: Intensity (deg) | C3: Tilt (deg, − = left) | D3: Response (1 = correct, 0 = incorrect) | E3: Key pressed (from log) | F3: 1-to-0 reversal? (1 = yes) | G3: Trial no. of reversal | H3: Re-scored correct (key vs tilt sign) | J3: Result | K3: Value
A4: =Data!A2+1 -> 1 | B4: =Data!C2 -> 10 | C4: =Data!O2 -> 10 | D4: =Data!Q2 -> 1 | E4: right | F4: 0 | G4: =IF(F4=1,A4,"") | H4: =IF(OR(AND(E4="right",C4>0),AND(E4="left",C4<0)),1,0) -> 1 | J4: Total trials | K4: =COUNT(A4:A103) -> 100
A5: =Data!A3+1 -> 2 | B5: =Data!C3 -> 8 | C5: =Data!O3 -> 8 | D5: =Data!Q3 -> 1 | E5: right | F5: =IF(AND(D4=1,D5=0),1,0) -> 0 | G5: =IF(F5=1,A5,"") | H5: =IF(OR(AND(E5="right",C5>0),AND(E5="left",C5<0)),1,0) -> 1 | J5: Total 1-to-0 reversals | K5: =SUM(F4:F103) -> 28
A6: =Data!A4+1 -> 3 | B6: =Data!C4 -> 6 | C6: =Data!O4 -> 6 | D6: =Data!Q4 -> 1 | E6: right | F6: =IF(AND(D5=1,D6=0),1,0) -> 0 | G6: =IF(F6=1,A6,"") | H6: =IF(OR(AND(E6="right",C6>0),AND(E6="left",C6<0)),1,0) -> 1 | J6: Overall accuracy (as recorded by PsychoPy) | K6: =AVERAGE(D4:D103) -> 0.5
A7: =Data!A5+1 -> 4 | B7: =Data!C5 -> 4 | C7: =Data!O5 -> -4 | D7: =Data!Q5 -> 0 | E7: left | F7: =IF(AND(D6=1,D7=0),1,0) -> 1 | G7: =IF(F7=1,A7,"") -> 4 | H7: =IF(OR(AND(E7="right",C7>0),AND(E7="left",C7<0)),1,0) -> 1
A8: =Data!A6+1 -> 5 | B8: =Data!C6 -> 5 | C8: =Data!O6 -> -5 | D8: =Data!Q6 -> 1 | E8: right | F8: =IF(AND(D7=1,D8=0),1,0) -> 0 | G8: =IF(F8=1,A8,"") | H8: =IF(OR(AND(E8="right",C8>0),AND(E8="left",C8<0)),1,0) -> 0 | J8: Last five 1-to-0 reversals | K8: Trial no. | L8: Intensity (deg)
A9: =Data!A7+1 -> 6 | B9: =Data!C7 -> 5 | C9: =Data!O7 -> 5 | D9: =Data!Q7 -> 0 | E9: left | F9: =IF(AND(D8=1,D9=0),1,0) -> 1 | G9: =IF(F9=1,A9,"") -> 6 | H9: =IF(OR(AND(E9="right",C9>0),AND(E9="left",C9<0)),1,0) -> 0 | J9: Reversal 5 of 5 (from the end: 1) | K9: =LARGE($G$4:$G$103,1) -> 100 | L9: =INDEX($B$4:$B$103,MATCH(K9,$A$4:$A$103,0)) -> 19.5
A10: =Data!A8+1 -> 7 | B10: =Data!C8 -> 6 | C10: =Data!O8 -> 6 | D10: =Data!Q8 -> 1 | E10: right | F10: =IF(AND(D9=1,D10=0),1,0) -> 0 | G10: =IF(F10=1,A10,"") | H10: =IF(OR(AND(E10="right",C10>0),AND(E10="left",C10<0)),1,0) -> 1 | J10: Reversal 4 of 5 (from the end: 2) | K10: =LARGE($G$4:$G$103,2) -> 96 | L10: =INDEX($B$4:$B$103,MATCH(K10,$A$4:$A$103,0)) -> 20
A11: =Data!A9+1 -> 8 | B11: =Data!C9 -> 6 | C11: =Data!O9 -> -6 | D11: =Data!Q9 -> 0 | E11: left | F11: =IF(AND(D10=1,D11=0),1,0) -> 1 | G11: =IF(F11=1,A11,"") -> 8 | H11: =IF(OR(AND(E11="right",C11>0),AND(E11="left",C11<0)),1,0) -> 1 | J11: Reversal 3 of 5 (from the end: 3) | K11: =LARGE($G$4:$G$103,3) -> 94 | L11: =INDEX($B$4:$B$103,MATCH(K11,$A$4:$A$103,0)) -> 20
A12: =Data!A10+1 -> 9 | B12: =Data!C10 -> 7 | C12: =Data!O10 -> 7 | D12: =Data!Q10 -> 1 | E12: right | F12: =IF(AND(D11=1,D12=0),1,0) -> 0 | G12: =IF(F12=1,A12,"") | H12: =IF(OR(AND(E12="right",C12>0),AND(E12="left",C12<0)),1,0) -> 1 | J12: Reversal 2 of 5 (from the end: 4) | K12: =LARGE($G$4:$G$103,4) -> 89 | L12: =INDEX($B$4:$B$103,MATCH(K12,$A$4:$A$103,0)) -> 20
A13: =Data!A11+1 -> 10 | B13: =Data!C11 -> 7 | C13: =Data!O11 -> 7 | D13: =Data!Q11 -> 1 | E13: right | F13: =IF(AND(D12=1,D13=0),1,0) -> 0 | G13: =IF(F13=1,A13,"") | H13: =IF(OR(AND(E13="right",C13>0),AND(E13="left",C13<0)),1,0) -> 1 | J13: Reversal 1 of 5 (from the end: 5) | K13: =LARGE($G$4:$G$103,5) -> 84 | L13: =INDEX($B$4:$B$103,MATCH(K13,$A$4:$A$103,0)) -> 20
A14: =Data!A12+1 -> 11 | B14: =Data!C12 -> 7 | C14: =Data!O12 -> 7 | D14: =Data!Q12 -> 1 | E14: right | F14: =IF(AND(D13=1,D14=0),1,0) -> 0 | G14: =IF(F14=1,A14,"") | H14: =IF(OR(AND(E14="right",C14>0),AND(E14="left",C14<0)),1,0) -> 1
A15: =Data!A13+1 -> 12 | B15: =Data!C13 -> 6 | C15: =Data!O13 -> -6 | D15: =Data!Q13 -> 0 | E15: left | F15: =IF(AND(D14=1,D15=0),1,0) -> 1 | G15: =IF(F15=1,A15,"") -> 12 | H15: =IF(OR(AND(E15="right",C15>0),AND(E15="left",C15<0)),1,0) -> 1 | J15: DIFFERENCE THRESHOLD (mean of last five 1-to-0 reversals, deg) | K15: =AVERAGE(L9:L13) -> 19.9
A16: =Data!A14+1 -> 13 | B16: =Data!C14 -> 6.5 | C16: =Data!O14 -> 6.5 | D16: =Data!Q14 -> 1 | E16: right | F16: =IF(AND(D15=1,D16=0),1,0) -> 0 | G16: =IF(F16=1,A16,"") | H16: =IF(OR(AND(E16="right",C16>0),AND(E16="left",C16<0)),1,0) -> 1
A17: =Data!A15+1 -> 14 | B17: =Data!C15 -> 6.5 | C17: =Data!O15 -> 6.5 | D17: =Data!Q15 -> 1 | E17: right | F17: =IF(AND(D16=1,D17=0),1,0) -> 0 | G17: =IF(F17=1,A17,"") | H17: =IF(OR(AND(E17="right",C17>0),AND(E17="left",C17<0)),1,0) -> 1 | J17: Supplementary check (re-scored from key presses)
A18: =Data!A16+1 -> 15 | B18: =Data!C16 -> 6.5 | C18: =Data!O16 -> -6.5 | D18: =Data!Q16 -> 0 | E18: left | F18: =IF(AND(D17=1,D18=0),1,0) -> 1 | G18: =IF(F18=1,A18,"") -> 15 | H18: =IF(OR(AND(E18="right",C18>0),AND(E18="left",C18<0)),1,0) -> 1 | J18: Proportion of trials answered "right" | K18: =COUNTIF(E4:E103,"right")/COUNT(A4:A103) -> 0.5
A19: =Data!A17+1 -> 16 | B19: =Data!C17 -> 7 | C19: =Data!O17 -> -7 | D19: =Data!Q17 -> 1 | E19: right | F19: =IF(AND(D18=1,D19=0),1,0) -> 0 | G19: =IF(F19=1,A19,"") | H19: =IF(OR(AND(E19="right",C19>0),AND(E19="left",C19<0)),1,0) -> 0 | J19: Accuracy re-scored from key vs tilt direction | K19: =AVERAGE(H4:H103) -> 0.88
A20: =Data!A18+1 -> 17 | B20: =Data!C18 -> 7 | C20: =Data!O18 -> -7 | D20: =Data!Q18 -> 0 | E20: left | F20: =IF(AND(D19=1,D20=0),1,0) -> 1 | G20: =IF(F20=1,A20,"") -> 17 | H20: =IF(OR(AND(E20="right",C20>0),AND(E20="left",C20<0)),1,0) -> 1 | J20: Mean response time (s) | K20: =AVERAGE(Data!R2:R101) -> 0.39873703
A21: =Data!A19+1 -> 18 | B21: =Data!C19 -> 7.5 | C21: =Data!O19 -> 7.5 | D21: =Data!Q19 -> 1 | E21: right | F21: =IF(AND(D20=1,D21=0),1,0) -> 0 | G21: =IF(F21=1,A21,"") | H21: =IF(OR(AND(E21="right",C21>0),AND(E21="left",C21<0)),1,0) -> 1 | J21: Maximum intensity reached (deg) | K21: =MAX(B4:B103) -> 20
A22: =Data!A20+1 -> 19 | B22: =Data!C20 -> 7.5 | C22: =Data!O20 -> -7.5 | D22: =Data!Q20 -> 0 | E22: left | F22: =IF(AND(D21=1,D22=0),1,0) -> 1 | G22: =IF(F22=1,A22,"") -> 19 | H22: =IF(OR(AND(E22="right",C22>0),AND(E22="left",C22<0)),1,0) -> 1 | J22: Trials presented at maximum intensity | K22: =COUNTIF(B4:B103,MAX(B4:B103)) -> 32
A23: =Data!A21+1 -> 20 | B23: =Data!C21 -> 8 | C23: =Data!O21 -> -8 | D23: =Data!Q21 -> 1 | E23: right | F23: =IF(AND(D22=1,D23=0),1,0) -> 0 | G23: =IF(F23=1,A23,"") | H23: =IF(OR(AND(E23="right",C23>0),AND(E23="left",C23<0)),1,0) -> 0
A24: =Data!A22+1 -> 21 | B24: =Data!C22 -> 8 | C24: =Data!O22 -> 8 | D24: =Data!Q22 -> 1 | E24: right | F24: =IF(AND(D23=1,D24=0),1,0) -> 0 | G24: =IF(F24=1,A24,"") | H24: =IF(OR(AND(E24="right",C24>0),AND(E24="left",C24<0)),1,0) -> 1 | J24: Notes
A25: =Data!A23+1 -> 22 | B25: =Data!C23 -> 8 | C25: =Data!O23 -> -8 | D25: =Data!Q23 -> 0 | E25: left | F25: =IF(AND(D24=1,D25=0),1,0) -> 1 | G25: =IF(F25=1,A25,"") -> 22 | H25: =IF(OR(AND(E25="right",C25>0),AND(E25="left",C25<0)),1,0) -> 1 | J25: A 1-to-0 reversal = a trial answered incorrectly (0) straight after a correct one (1); the intensity of that incorrect trial is used.
A26: =Data!A24+1 -> 23 | B26: =Data!C24 -> 8.5 | C26: =Data!O24 -> 8.5 | D26: =Data!Q24 -> 1 | E26: right | F26: =IF(AND(D25=1,D26=0),1,0) -> 0 | G26: =IF(F26=1,A26,"") | H26: =IF(OR(AND(E26="right",C26>0),AND(E26="left",C26<0)),1,0) -> 1 | J26: The recorded correctness equals "key = right" on every trial, because corrAns is fixed to "right" in the PsychoPy file.
A27: =Data!A25+1 -> 24 | B27: =Data!C25 -> 8.5 | C27: =Data!O25 -> 8.5 | D27: =Data!Q25 -> 1 | E27: right | F27: =IF(AND(D26=1,D27=0),1,0) -> 0 | G27: =IF(F27=1,A27,"") | H27: =IF(OR(AND(E27="right",C27>0),AND(E27="left",C27<0)),1,0) -> 1 | J27: Because the staircase was driven by that recorded response, it climbed to the 20 deg ceiling instead of converging.
A28: =Data!A26+1 -> 25 | B28: =Data!C26 -> 8.5 | C28: =Data!O26 -> -8.5 | D28: =Data!Q26 -> 0 | E28: left | F28: =IF(AND(D27=1,D28=0),1,0) -> 1 | G28: =IF(F28=1,A28,"") -> 25 | H28: =IF(OR(AND(E28="right",C28>0),AND(E28="left",C28<0)),1,0) -> 1 | J28: The log lists 101 key presses; one stray press (at 88.18 s, between trials 98 and 99) was left out so the keys line up with the 100 trials.
A29: =Data!A27+1 -> 26 | B29: =Data!C27 -> 9 | C29: =Data!O27 -> -9 | D29: =Data!Q27 -> 1 | E29: right | F29: =IF(AND(D28=1,D29=0),1,0) -> 0 | G29: =IF(F29=1,A29,"") | H29: =IF(OR(AND(E29="right",C29>0),AND(E29="left",C29<0)),1,0) -> 0
A30: =Data!A28+1 -> 27 | B30: =Data!C28 -> 9 | C30: =Data!O28 -> 9 | D30: =Data!Q28 -> 1 | E30: right | F30: =IF(AND(D29=1,D30=0),1,0) -> 0 | G30: =IF(F30=1,A30,"") | H30: =IF(OR(AND(E30="right",C30>0),AND(E30="left",C30<0)),1,0) -> 1
A31: =Data!A29+1 -> 28 | B31: =Data!C29 -> 9 | C31: =Data!O29 -> 9 | D31: =Data!Q29 -> 1 | E31: right | F31: =IF(AND(D30=1,D31=0),1,0) -> 0 | G31: =IF(F31=1,A31,"") | H31: =IF(OR(AND(E31="right",C31>0),AND(E31="left",C31<0)),1,0) -> 1
A32: =Data!A30+1 -> 29 | B32: =Data!C30 -> 8.5 | C32: =Data!O30 -> -8.5 | D32: =Data!Q30 -> 0 | E32: left | F32: =IF(AND(D31=1,D32=0),1,0) -> 1 | G32: =IF(F32=1,A32,"") -> 29 | H32: =IF(OR(AND(E32="right",C32>0),AND(E32="left",C32<0)),1,0) -> 1
A33: =Data!A31+1 -> 30 | B33: =Data!C31 -> 9 | C33: =Data!O31 -> -9 | D33: =Data!Q31 -> 1 | E33: right | F33: =IF(AND(D32=1,D33=0),1,0) -> 0 | G33: =IF(F33=1,A33,"") | H33: =IF(OR(AND(E33="right",C33>0),AND(E33="left",C33<0)),1,0) -> 0
A34: =Data!A32+1 -> 31 | B34: =Data!C32 -> 9 | C34: =Data!O32 -> -9 | D34: =Data!Q32 -> 0 | E34: left | F34: =IF(AND(D33=1,D34=0),1,0) -> 1 | G34: =IF(F34=1,A34,"") -> 31 | H34: =IF(OR(AND(E34="right",C34>0),AND(E34="left",C34<0)),1,0) -> 1
A35: =Data!A33+1 -> 32 | B35: =Data!C33 -> 9.5 | C35: =Data!O33 -> -9.5 | D35: =Data!Q33 -> 0 | E35: left | F35: =IF(AND(D34=1,D35=0),1,0) -> 0 | G35: =IF(F35=1,A35,"") | H35: =IF(OR(AND(E35="right",C35>0),AND(E35="left",C35<0)),1,0) -> 1
A36: =Data!A34+1 -> 33 | B36: =Data!C34 -> 10 | C36: =Data!O34 -> 10 | D36: =Data!Q34 -> 1 | E36: right | F36: =IF(AND(D35=1,D36=0),1,0) -> 0 | G36: =IF(F36=1,A36,"") | H36: =IF(OR(AND(E36="right",C36>0),AND(E36="left",C36<0)),1,0) -> 1
A37: =Data!A35+1 -> 34 | B37: =Data!C35 -> 10 | C37: =Data!O35 -> -10 | D37: =Data!Q35 -> 0 | E37: left | F37: =IF(AND(D36=1,D37=0),1,0) -> 1 | G37: =IF(F37=1,A37,"") -> 34 | H37: =IF(OR(AND(E37="right",C37>0),AND(E37="left",C37<0)),1,0) -> 1
A38: =Data!A36+1 -> 35 | B38: =Data!C36 -> 10.5 | C38: =Data!O36 -> -10.5 | D38: =Data!Q36 -> 0 | E38: left | F38: =IF(AND(D37=1,D38=0),1,0) -> 0 | G38: =IF(F38=1,A38,"") | H38: =IF(OR(AND(E38="right",C38>0),AND(E38="left",C38<0)),1,0) -> 1
A39: =Data!A37+1 -> 36 | B39: =Data!C37 -> 11 | C39: =Data!O37 -> -11 | D39: =Data!Q37 -> 0 | E39: left | F39: =IF(AND(D38=1,D39=0),1,0) -> 0 | G39: =IF(F39=1,A39,"") | H39: =IF(OR(AND(E39="right",C39>0),AND(E39="left",C39<0)),1,0) -> 1
A40: =Data!A38+1 -> 37 | B40: =Data!C38 -> 11.5 | C40: =Data!O38 -> -11.5 | D40: =Data!Q38 -> 0 | E40: left | F40: =IF(AND(D39=1,D40=0),1,0) -> 0 | G40: =IF(F40=1,A40,"") | H40: =IF(OR(AND(E40="right",C40>0),AND(E40="left",C40<0)),1,0) -> 1
...

Sheet Figures
A1: Figures (identical to the figures in the lab report)
A16: Figure 1. Stimulus - Sinusoidal grating with a Gaussian mask with a Right tilt
A35: Figure 2. A graph representing the changes in tilt across the 100 trials of the procedure.
A53: Figure 3. A graph representing the tilt intensity (without direction) across the 100 trials of the procedure.
A69: Figure 4. Graph representing the accuracy of responses over the 100 trials, as recorded by PsychoPy.
